Workbook

Sheet Leia-me
A1: Apêndice E1 — Custos mensais de IA por piloto
A2: Grupo Meridiano · set/2025 a ago/2026 · valores em R$
A4: O que é
A5: Estimativa do gasto mensal com IA de cada piloto do inventário (Apêndice A1), reconstruída pela área de Finanças a partir de faturas de nuvem, contratos de fornecedores, faturas de cartão corporativo e métricas de uso. Inclui uma linha de recursos de nuvem sem piloto atribuído.
A7: Estrutura
A8: Premissas: câmbio, fator de escala e tabela de preços dos modelos de linguagem.
A9: Volumes: volumes mensais que puxam o custo variável de cada piloto.
A10: Parâmetros: como cada piloto consome (tokens por unidade, custo unitário, custo fixo, mês de início).
A11: Custos: cálculo mês a mês, separado em custo variável e custo fixo, com totais por piloto e por unidade.
A12: Gráfico: gasto mensal por unidade.
A14: Convenções
A15: Azul: valores de entrada. Preto: fórmulas. Alterar uma premissa recalcula todo o arquivo.
... A22: Volumes de pedidos e de atrasos: base amostral de pedidos do marketplace × fator de escala. Dados adaptados da base pública da Olist (licença MIT).

Sheet Premissas
A1: Premissas gerais
A2: Câmbio (R$ por US$) | B2: 5.15 | C2: Referência de set/2026.
A3: Fator de escala (empresa ÷ amostra) | B3: 200 | C3: A base amostral corresponde a 0,5% dos pedidos.
A5: Preços de modelos de linguagem (US$ por 1 milhão de tokens)
A6: Porte | B6: Código | C6: Entrada | D6: Saída | E6: Referência de mercado (07/10/2026)
A7: Fronteira | B7: F | C7: 2 | D7: 12 | E7: Gemini 3.1 Pro, prompts até 200 mil tokens
A8: Intermediário | B8: I | C8: 0.75 | D8: 3.75 | E8: Gemini 3.8 Flash, preço válido até 31/12/2026; passa a US$ 1,50 / US$ 7,50 em 01/01/2027
A9: Leve | B9: L | C9: 0.25 | D9: 1.5 | E9: Gemini 3.1 Flash-Lite

Sheet Volumes
A1: Volumes mensais
A2: Chave | B2: Descrição | C2: set/25 | D2: out/25 | E2: nov/25 | F2: dez/25 | G2: jan/26 | H2: fev/26 | I2: mar/26 | J2: abr/26 | K2: mai/26 | L2: jun/26 | M2: jul/26 | N2: ago/26
A3: pedidos_amostra | B3: Pedidos na amostra | C3: 4387 | D3: 4622 | E3: 6700 | F3: 6594 | G3: 6805 | H3: 6497 | I3: 7611 | J3: 6864 | K3: 7130 | L3: 5976 | M3: 6074 | N3: 7423
A4: atrasados_amostra | B4: Pedidos entregues com atraso na amostra | C4: 229 | D4: 214 | E4: 824 | F4: 702 | G4: 403 | H4: 819 | I4: 1700 | J4: 426 | K4: 591 | L4: 76 | M4: 196 | N4: 744
A6: Volumes da empresa (direcionadores de custo)
A7: Chave | B7: Descrição | C7: set/25 | D7: out/25 | E7: nov/25 | F7: dez/25 | G7: jan/26 | H7: fev/26 | I7: mar/26 | J7: abr/26 | K7: mai/26 | L7: jun/26 | M7: jul/26 | N7: ago/26
A8: pedidos | B8: Pedidos do marketplace | C8: =C3*Premissas!$B$3 -> 877400 | D8: =D3*Premissas!$B$3 -> 924400 | E8: =E3*Premissas!$B$3 -> 1340000 | F8: =F3*Premissas!$B$3 -> 1318800 | G8: =G3*Premissas!$B$3 -> 1361000 | H8: =H3*Premissas!$B$3 -> 1299400 | I8: =I3*Premissas!$B$3 -> 1522200 | J8: =J3*Premissas!$B$3 -> 1372800 | ... N8: =N3*Premissas!$B$3 -> 1484600
A9: atrasados | B9: Pedidos entregues com atraso | C9: =C4*Premissas!$B$3 -> 45800 | D9: =D4*Premissas!$B$3 -> 42800 | E9: =E4*Premissas!$B$3 -> 164800 | F9: =F4*Premissas!$B$3 -> 140400 | G9: =G4*Premissas!$B$3 -> 80600 | H9: =H4*Premissas!$B$3 -> 163800 | I9: =I4*Premissas!$B$3 -> 340000 | J9: =J4*Premissas!$B$3 -> 85200 | ... N9: =N4*Premissas!$B$3 -> 148800
A10: clientes_campanha | B10: Clientes impactados por campanhas personalizadas | C10: 500000 | D10: 500000 | E10: 500000 | F10: 500000 | G10: 500000 | H10: 500000 | I10: 500000 | J10: 500000 | K10: 500000 | L10: 500000 | M10: 500000 | N10: 500000
A11: consultas_rh | B11: Consultas ao assistente de RH | C11: 40000 | D11: 40000 | E11: 40000 | F11: 40000 | G11: 40000 | H11: 40000 | I11: 40000 | J11: 40000 | K11: 40000 | L11: 40000 | M11: 40000 | N11: 40000
A12: assentos_gerais | B12: Assinaturas individuais de IA (cartão corporativo) | C12: 120 | D12: 147 | E12: 175 | F12: 202 | G12: 229 | H12: 256 | I12: 284 | J12: 311 | K12: 338 | L12: 365 | M12: 393 | N12: 420
A13: fixo | B13: Sem volume (apenas custo fixo) | C13: 0 | D13: 0 | E13: 0 | F13: 0 | G13: 0 | H13: 0 | I13: 0 | J13: 0 | K13: 0 | L13: 0 | M13: 0 | N13: 0
A15: Volumes de campanhas, consultas de RH e assinaturas: registros internos das áreas responsáveis.

Sheet Parâmetros
A1: ID | B1: Piloto | C1: Unidade | D1: Direcionador (chave em Volumes) | E1: Taxa de uso sobre o volume | F1: Tokens de entrada por unidade | G1: Tokens de saída por unidade | H1: Porte do modelo | I1: Custo unitário (R$) | J1: Custo fixo mensal (R$) | K1: Início da cobrança | L1: Notas
A2: P01 | B2: Agente de SAC com RAG | C2: Marketplace e e-commerce | D2: pedidos | E2: 0.032 | F2: 180000 | G2: 2400 | H2: F | I2: 0 | J2: 12000 | K2: 46054 | L2: Taxa = 8% dos pedidos geram contato no SAC × 40% atendidos pelo agente. Tokens por conversa medidos nos logs (média de 6 trocas).
A3: P02 | B3: Recompra + campanhas personalizadas | C3: Marketplace e e-commerce | D3: clientes_campanha | E3: 1 | F3: 1500 | G3: 300 | H3: I | I3: 0 | J3: 12000 | K3: 45962 | L3: Custo fixo: treino e execução mensal do modelo de propensão na Nuvem A.
A4: P03 | B4: Agente de tratativa de atrasos | C4: Logística | D4: atrasados | E4: 1 | F4: 48000 | G4: 4000 | H4: F | I4: 0 | J4: 9000 | K4: 46082 | L4: Uma execução por pedido atrasado; média de 8 etapas por execução, medida nos logs da plataforma W. Custo fixo: licença da plataforma W (a consultoria é contratada à parte, fora desta planilha).
A5: P04 | B5: App de escala de equipe | C5: Lojas físicas | D5: fixo | E5: 0 | F5: 0 | G5: 0 | H5: L | I5: 0 | J5: 600 | K5: 46113 | L5: Hospedagem em conta pessoal paga com cartão corporativo.
A6: P05 | B6: Assistentes de IA de uso geral | C6: Lojas físicas e áreas corporativas | D6: assentos_gerais | E6: 1 | F6: 0 | G6: 0 | H6: L | I6: 110 | J6: 0 | K6: 45901 | L6: Assinaturas identificadas nas faturas de cartão corporativo.
A7: P06 | B7: Modelo de crédito a sellers | C7: Serviços financeiros | D7: fixo | E7: 0 | F7: 0 | G7: 0 | H7: L | I7: 0 | J7: 35000 | K7: 45901 | L7: Treino, execução mensal e armazenamento na Nuvem B.
A8: P07 | B8: Antifraude de pagamentos | C8: Serviços financeiros | D8: fixo | E8: 0 | F8: 0 | G8: 0 | H8: L | I8: 0 | J8: 95000 | K8: 45901 | L8: Contrato mensal do fornecedor.
A9: P08 | B9: Assistente interno de RH e políticas | C9: Corporativo | D9: consultas_rh | E9: 1 | F9: 10000 | G9: 500 | H9: F | I9: 0 | J9: 8000 | K9: 46143 | L9: Infraestrutura na Nuvem B e banco vetorial próprio.
A10: X1 | B10: Recursos de nuvem sem piloto atribuído | C10: Não atribuído | D10: fixo | E10: 0 | F10: 0 | G10: 0 | H10: L | I10: 0 | J10: 85000 | K10: 46113 | L10: Ambientes de desenvolvimento e teste e máquinas com GPU sem piloto associado, identificados na fatura da Nuvem A a partir de abr/2026.

Sheet Custos
A1: Custos mensais de IA (R$)
B2: Mês de referência | D2: 45901 | E2: 45931 | F2: 45962 | G2: 45992 | H2: 46023 | I2: 46054 | J2: 46082 | K2: 46113 | L2: 46143 | M2: 46174 | N2: 46204 | O2: 46235
A3: Custo variável (tokens e assinaturas por usuário)
A4: ID | B4: Piloto | C4: Unidade | D4: set/25 | E4: out/25 | F4: nov/25 | G4: dez/25 | H4: jan/26 | I4: fev/26 | J4: mar/26 | K4: abr/26 | L4: mai/26 | M4: jun/26 | N4: jul/26 | O4: ago/26 | P4: Total 12 meses
A5: =Parâmetros!A2 -> P01 | B5: =Parâmetros!B2 -> Agente de SAC com RAG | C5: =Parâmetros!C2 -> Marketplace e e-commerce | D5: =IF(D$2>=Parâmetros!$K2,INDEX(Volumes!$C$8:$C$13,MATCH(Parâmetros!$D2,Volumes!$A$8:$A$13,0))*Parâmetros!$E2*((Parâmetros!$F2*INDEX(Premissas!$C$7:$C$9,MATCH(Parâmetros!$H2,Premissas!$B$7:$B$9,0))+Parâmetros!$G2*INDEX(Premissas!$D$7:$D$9,MATCH(Parâmetros!$H2,Premissas!$B$7:$B$9,0)))/1000000*Premissas!$B$2+Parâmetros!$I2),0) -> 0 | E5: =IF(E$2>=Parâmetros!$K2,INDEX(Volumes!$D$8:$D$13,MATCH(Parâmetros!$D2,Volumes!$A$8:$A$13,0))*Parâmetros!$E2*((Parâmetros!$F2*INDEX(Premissas!$C$7:$C$9,MATCH(Parâmetros!$H2,Premissas!$B$7:$B$9,0))+Parâmetros!$G2*INDEX(Premissas!$D$7:$D$9,MATCH(Parâmetros!$H2,Premissas!$B$7:$B$9,0)))/1000000*Premissas!$B$2+Parâmetros!$I2),0) -> 0 | F5: =IF(F$2>=Parâmetros!$K2,INDEX(Volumes!$E$8:$E$13,MATCH(Parâmetros!$D2,Volumes!$A$8:$A$13,0))*Parâmetros!$E2*((Parâmetros!$F2*INDEX(Premissas!$C$7:$C$9,MATCH(Parâmetros!$H2,Premissas!$B$7:$B$9,0))+Parâmetros!$G2*INDEX(Premissas!$D$7:$D$9,MATCH(Parâmetros!$H2,Premissas!$B$7:$B$9,0)))/1000000*Premissas!$B$2+Parâmetros!$I2),0) -> 0 | G5: =IF(G$2>=Parâmetros!$K2,INDEX(Volumes!$F$8:$F$13,MATCH(Parâmetros!$D2,Volumes!$A$8:$A$13,0))*Parâmetros!$E2*((Parâmetros!$F2*INDEX(Premissas!$C$7:$C$9,MATCH(Parâmetros!$H2,Premissas!$B$7:$B$9,0))+Parâmetros!$G2*INDEX(Premissas!$D$7:$D$9,MATCH(Parâmetros!$H2,Premissas!$B$7:$B$9,0)))/1000000*Premissas!$B$2+Parâmetros!$I2),0) -> 0 | H5: =IF(H$2>=Parâmetros!$K2,INDEX(Volumes!$G$8:$G$13,MATCH(Parâmetros!$D2,Volumes!$A$8:$A$13,0))*Parâmetros!$E2*((Parâmetros!$F2*INDEX(Premissas!$C$7:$C$9,MATCH(Parâmetros!$H2,Premissas!$B$7:$B$9,0))+Parâmetros!$G2*INDEX(Premissas!$D$7:$D$9,MATCH(Parâmetros!$H2,Premissas!$B$7:$B$9,0)))/1000000*Premissas!$B$2+Parâmetros!$I2),0) -> 0 | I5: =IF(I$2>=Parâmetros!$K2,INDEX(Volumes!$H$8:$H$13,MATCH(Parâmetros!$D2,Volumes!$A$8:$A$13,0))*Parâmetros!$E2*((Parâmetros!$F2*INDEX(Premissas!$C$7:$C$9,MATCH(Parâmetros!$H2,Premissas!$B$7:$B$9,0))+Parâmetros!$G2*INDEX(Premissas!$D$7:$D$9,MATCH(Parâmetros!$H2,Premissas!$B$7:$B$9,0)))/1000000*Premissas!$B$2+Parâmetros!$I2),0) -> 83258.067 | J5: =IF(J$2>=Parâmetros!$K2,INDEX(Volumes!$I$8:$I$13,MATCH(Parâmetros!$D2,Volumes!$A$8:$A$13,0))*Parâmetros!$E2*((Parâmetros!$F2*INDEX(Premissas!$C$7:$C$9,MATCH(Parâmetros!$H2,Premissas!$B$7:$B$9,0))+Parâmetros!$G2*INDEX(Premissas!$D$7:$D$9,MATCH(Parâmetros!$H2,Premissas!$B$7:$B$9,0)))/1000000*Premissas!$B$2+Parâmetros!$I2),0) -> 97533.808 | K5: =IF(K$2>=Parâmetros!$K2,INDEX(Volumes!$J$8:$J$13,MATCH(Parâmetros!$D2,Volumes!$A$8:$A$13,0))*Parâmetros!$E2*((Parâmetros!$F2*INDEX(Premissas!$C$7:$C$9,MATCH(Parâmetros!$H2,Premissas!$B$7:$B$9,0))+Parâmetros!$G2*INDEX(Premissas!$D$7:$D$9,MATCH(Parâmetros!$H2,Premissas!$B$7:$B$9,0)))/1000000*Premissas!$B$2+Parâmetros!$I2),0) -> 87961.117 | L5: =IF(L$2>=Parâmetros!$K2,INDEX(Volumes!$K$8:$K$13,MATCH(Parâmetros!$D2,Volumes!$A$8:$A$13,0))*Parâmetros!$E2*((Parâmetros!$F2*INDEX(Premissas!$C$7:$C$9,MATCH(Parâmetros!$H2,Premissas!$B$7:$B$9,0))+Parâmetros!$G2*INDEX(Premissas!$D$7:$D$9,MATCH(Parâmetros!$H2,Premissas!$B$7:$B$9,0)))/1000000*Premissas!$B$2+Parâmetros!$I2),0) -> 91369.866 | M5: =IF(M$2>=Parâmetros!$K2,INDEX(Volumes!$L$8:$L$13,MATCH(Parâmetros!$D2,Volumes!$A$8:$A$13,0))*Parâmetros!$E2*((Parâmetros!$F2*INDEX(Premissas!$C$7:$C$9,MATCH(Parâmetros!$H2,Premissas!$B$7:$B$9,0))+Parâmetros!$G2*INDEX(Premissas!$D$7:$D$9,MATCH(Parâmetros!$H2,Premissas!$B$7:$B$9,0)))/1000000*Premissas!$B$2+Parâmetros!$I2),0) -> 76581.532 | N5: =IF(N$2>=Parâmetros!$K2,INDEX(Volumes!$M$8:$M$13,MATCH(Parâmetros!$D2,Volumes!$A$8:$A$13,0))*Parâmetros!$E2*((Parâmetros!$F2*INDEX(Premissas!$C$7:$C$9,MATCH(Parâmetros!$H2,Premissas!$B$7:$B$9,0))+Parâmetros!$G2*INDEX(Premissas!$D$7:$D$9,MATCH(Parâmetros!$H2,Premissas!$B$7:$B$9,0)))/1000000*Premissas!$B$2+Parâmetros!$I2),0) -> 77837.387 | O5: =IF(O$2>=Parâmetros!$K2,INDEX(Volumes!$N$8:$N$13,MATCH(Parâmetros!$D2,Volumes!$A$8:$A$13,0))*Parâmetros!$E2*((Parâmetros!$F2*INDEX(Premissas!$C$7:$C$9,MATCH(Parâmetros!$H2,Premissas!$B$7:$B$9,0))+Parâmetros!$G2*INDEX(Premissas!$D$7:$D$9,MATCH(Parâmetros!$H2,Premissas!$B$7:$B$9,0)))/1000000*Premissas!$B$2+Parâmetros!$I2),0) -> 95124.617 | P5: =SUM(D5:O5) -> 609666.39
A6: =Parâmetros!A3 -> P02 | B6: =Parâmetros!B3 -> Recompra + campanhas personalizadas | C6: =Parâmetros!C3 -> Marketplace e e-commerce | D6: =IF(D$2>=Parâmetros!$K3,INDEX(Volumes!$C$8:$C$13,MATCH(Parâmetros!$D3,Volumes!$A$8:$A$13,0))*Parâmetros!$E3*((Parâmetros!$F3*INDEX(Premissas!$C$7:$C$9,MATCH(Parâmetros!$H3,Premissas!$B$7:$B$9,0))+Parâmetros!$G3*INDEX(Premissas!$D$7:$D$9,MATCH(Parâmetros!$H3,Premissas!$B$7:$B$9,0)))/1000000*Premissas!$B$2+Parâmetros!$I3),0) -> 0 | E6: =IF(E$2>=Parâmetros!$K3,INDEX(Volumes!$D$8:$D$13,MATCH(Parâmetros!$D3,Volumes!$A$8:$A$13,0))*Parâmetros!$E3*((Parâmetros!$F3*INDEX(Premissas!$C$7:$C$9,MATCH(Parâmetros!$H3,Premissas!$B$7:$B$9,0))+Parâmetros!$G3*INDEX(Premissas!$D$7:$D$9,MATCH(Parâmetros!$H3,Premissas!$B$7:$B$9,0)))/1000000*Premissas!$B$2+Parâmetros!$I3),0) -> 0 | F6: =IF(F$2>=Parâmetros!$K3,INDEX(Volumes!$E$8:$E$13,MATCH(Parâmetros!$D3,Volumes!$A$8:$A$13,0))*Parâmetros!$E3*((Parâmetros!$F3*INDEX(Premissas!$C$7:$C$9,MATCH(Parâmetros!$H3,Premissas!$B$7:$B$9,0))+Parâmetros!$G3*INDEX(Premissas!$D$7:$D$9,MATCH(Parâmetros!$H3,Premissas!$B$7:$B$9,0)))/1000000*Premissas!$B$2+Parâmetros!$I3),0) -> 5793.75 | G6: =IF(G$2>=Parâmetros!$K3,INDEX(Volumes!$F$8:$F$13,MATCH(Parâmetros!$D3,Volumes!$A$8:$A$13,0))*Parâmetros!$E3*((Parâmetros!$F3*INDEX(Premissas!$C$7:$C$9,MATCH(Parâmetros!$H3,Premissas!$B$7:$B$9,0))+Parâmetros!$G3*INDEX(Premissas!$D$7:$D$9,MATCH(Parâmetros!$H3,Premissas!$B$7:$B$9,0)))/1000000*Premissas!$B$2+Parâmetros!$I3),0) -> 5793.75 | H6: =IF(H$2>=Parâmetros!$K3,INDEX(Volumes!$G$8:$G$13,MATCH(Parâmetros!$D3,Volumes!$A$8:$A$13,0))*Parâmetros!$E3*((Parâmetros!$F3*INDEX(Premissas!$C$7:$C$9,MATCH(Parâmetros!$H3,Premissas!$B$7:$B$9,0))+Parâmetros!$G3*INDEX(Premissas!$D$7:$D$9,MATCH(Parâmetros!$H3,Premissas!$B$7:$B$9,0)))/1000000*Premissas!$B$2+Parâmetros!$I3),0) -> 5793.75 | I6: =IF(I$2>=Parâmetros!$K3,INDEX(Volumes!$H$8:$H$13,MATCH(Parâmetros!$D3,Volumes!$A$8:$A$13,0))*Parâmetros!$E3*((Parâmetros!$F3*INDEX(Premissas!$C$7:$C$9,MATCH(Parâmetros!$H3,Premissas!$B$7:$B$9,0))+Parâmetros!$G3*INDEX(Premissas!$D$7:$D$9,MATCH(Parâmetros!$H3,Premissas!$B$7:$B$9,0)))/1000000*Premissas!$B$2+Parâmetros!$I3),0) -> 5793.75 | J6: =IF(J$2>=Parâmetros!$K3,INDEX(Volumes!$I$8:$I$13,MATCH(Parâmetros!$D3,Volumes!$A$8:$A$13,0))*Parâmetros!$E3*((Parâmetros!$F3*INDEX(Premissas!$C$7:$C$9,MATCH(Parâmetros!$H3,Premissas!$B$7:$B$9,0))+Parâmetros!$G3*INDEX(Premissas!$D$7:$D$9,MATCH(Parâmetros!$H3,Premissas!$B$7:$B$9,0)))/1000000*Premissas!$B$2+Parâmetros!$I3),0) -> 5793.75 | K6: =IF(K$2>=Parâmetros!$K3,INDEX(Volumes!$J$8:$J$13,MATCH(Parâmetros!$D3,Volumes!$A$8:$A$13,0))*Parâmetros!$E3*((Parâmetros!$F3*INDEX(Premissas!$C$7:$C$9,MATCH(Parâmetros!$H3,Premissas!$B$7:$B$9,0))+Parâmetros!$G3*INDEX(Premissas!$D$7:$D$9,MATCH(Parâmetros!$H3,Premissas!$B$7:$B$9,0)))/1000000*Premissas!$B$2+Parâmetros!$I3),0) -> 5793.75 | L6: =IF(L$2>=Parâmetros!$K3,INDEX(Volumes!$K$8:$K$13,MATCH(Parâmetros!$D3,Volumes!$A$8:$A$13,0))*Parâmetros!$E3*((Parâmetros!$F3*INDEX(Premissas!$C$7:$C$9,MATCH(Parâmetros!$H3,Premissas!$B$7:$B$9,0))+Parâmetros!$G3*INDEX(Premissas!$D$7:$D$9,MATCH(Parâmetros!$H3,Premissas!$B$7:$B$9,0)))/1000000*Premissas!$B$2+Parâmetros!$I3),0) -> 5793.75 | M6: =IF(M$2>=Parâmetros!$K3,INDEX(Volumes!$L$8:$L$13,MATCH(Parâmetros!$D3,Volumes!$A$8:$A$13,0))*Parâmetros!$E3*((Parâmetros!$F3*INDEX(Premissas!$C$7:$C$9,MATCH(Parâmetros!$H3,Premissas!$B$7:$B$9,0))+Parâmetros!$G3*INDEX(Premissas!$D$7:$D$9,MATCH(Parâmetros!$H3,Premissas!$B$7:$B$9,0)))/1000000*Premissas!$B$2+Parâmetros!$I3),0) -> 5793.75 | N6: =IF(N$2>=Parâmetros!$K3,INDEX(Volumes!$M$8:$M$13,MATCH(Parâmetros!$D3,Volumes!$A$8:$A$13,0))*Parâmetros!$E3*((Parâmetros!$F3*INDEX(Premissas!$C$7:$C$9,MATCH(Parâmetros!$H3,Premissas!$B$7:$B$9,0))+Parâmetros!$G3*INDEX(Premissas!$D$7:$D$9,MATCH(Parâmetros!$H3,Premissas!$B$7:$B$9,0)))/1000000*Premissas!$B$2+Parâmetros!$I3),0) -> 5793.75 | O6: =IF(O$2>=Parâmetros!$K3,INDEX(Volumes!$N$8:$N$13,MATCH(Parâmetros!$D3,Volumes!$A$8:$A$13,0))*Parâmetros!$E3*((Parâmetros!$F3*INDEX(Premissas!$C$7:$C$9,MATCH(Parâmetros!$H3,Premissas!$B$7:$B$9,0))+Parâmetros!$G3*INDEX(Premissas!$D$7:$D$9,MATCH(Parâmetros!$H3,Premissas!$B$7:$B$9,0)))/1000000*Premissas!$B$2+Parâmetros!$I3),0) -> 5793.75 | P6: =SUM(D6:O6) -> 57937.5
A7: =Parâmetros!A4 -> P03 | B7: =Parâmetros!B4 -> Agente de tratativa de atrasos | C7: =Parâmetros!C4 -> Logística | D7: =IF(D$2>=Parâmetros!$K4,INDEX(Volumes!$C$8:$C$13,MATCH(Parâmetros!$D4,Volumes!$A$8:$A$13,0))*Parâmetros!$E4*((Parâmetros!$F4*INDEX(Premissas!$C$7:$C$9,MATCH(Parâmetros!$H4,Premissas!$B$7:$B$9,0))+Parâmetros!$G4*INDEX(Premissas!$D$7:$D$9,MATCH(Parâmetros!$H4,Premissas!$B$7:$B$9,0)))/1000000*Premissas!$B$2+Parâmetros!$I4),0) -> 0 | E7: =IF(E$2>=Parâmetros!$K4,INDEX(Volumes!$D$8:$D$13,MATCH(Parâmetros!$D4,Volumes!$A$8:$A$13,0))*Parâmetros!$E4*((Parâmetros!$F4*INDEX(Premissas!$C$7:$C$9,MATCH(Parâmetros!$H4,Premissas!$B$7:$B$9,0))+Parâmetros!$G4*INDEX(Premissas!$D$7:$D$9,MATCH(Parâmetros!$H4,Premissas!$B$7:$B$9,0)))/1000000*Premissas!$B$2+Parâmetros!$I4),0) -> 0 | F7: =IF(F$2>=Parâmetros!$K4,INDEX(Volumes!$E$8:$E$13,MATCH(Parâmetros!$D4,Volumes!$A$8:$A$13,0))*Parâmetros!$E4*((Parâmetros!$F4*INDEX(Premissas!$C$7:$C$9,MATCH(Parâmetros!$H4,Premissas!$B$7:$B$9,0))+Parâmetros!$G4*INDEX(Premissas!$D$7:$D$9,MATCH(Parâmetros!$H4,Premissas!$B$7:$B$9,0)))/1000000*Premissas!$B$2+Parâmetros!$I4),0) -> 0 | G7: =IF(G$2>=Parâmetros!$K4,INDEX(Volumes!$F$8:$F$13,MATCH(Parâmetros!$D4,Volumes!$A$8:$A$13,0))*Parâmetros!$E4*((Parâmetros!$F4*INDEX(Premissas!$C$7:$C$9,MATCH(Parâmetros!$H4,Premissas!$B$7:$B$9,0))+Parâmetros!$G4*INDEX(Premissas!$D$7:$D$9,MATCH(Parâmetros!$H4,Premissas!$B$7:$B$9,0)))/1000000*Premissas!$B$2+Parâmetros!$I4),0) -> 0 | H7: =IF(H$2>=Parâmetros!$K4,INDEX(Volumes!$G$8:$G$13,MATCH(Parâmetros!$D4,Volumes!$A$8:$A$13,0))*Parâmetros!$E4*((Parâmetros!$F4*INDEX(Premissas!$C$7:$C$9,MATCH(Parâmetros!$H4,Premissas!$B$7:$B$9,0))+Parâmetros!$G4*INDEX(Premissas!$D$7:$D$9,MATCH(Parâmetros!$H4,Premissas!$B$7:$B$9,0)))/1000000*Premissas!$B$2+Parâmetros!$I4),0) -> 0 | I7: =IF(I$2>=Parâmetros!$K4,INDEX(Volumes!$H$8:$H$13,MATCH(Parâmetros!$D4,Volumes!$A$8:$A$13,0))*Parâmetros!$E4*((Parâmetros!$F4*INDEX(Premissas!$C$7:$C$9,MATCH(Parâmetros!$H4,Premissas!$B$7:$B$9,0))+Parâmetros!$G4*INDEX(Premissas!$D$7:$D$9,MATCH(Parâmetros!$H4,Premissas!$B$7:$B$9,0)))/1000000*Premissas!$B$2+Parâmetros!$I4),0) -> 0 | J7: =IF(J$2>=Parâmetros!$K4,INDEX(Volumes!$I$8:$I$13,MATCH(Parâmetros!$D4,Volumes!$A$8:$A$13,0))*Parâmetros!$E4*((Parâmetros!$F4*INDEX(Premissas!$C$7:$C$9,MATCH(Parâmetros!$H4,Premissas!$B$7:$B$9,0))+Parâmetros!$G4*INDEX(Premissas!$D$7:$D$9,MATCH(Parâmetros!$H4,Premissas!$B$7:$B$9,0)))/1000000*Premissas!$B$2+Parâmetros!$I4),0) -> 252144 | K7: =IF(K$2>=Parâmetros!$K4,INDEX(Volumes!$J$8:$J$13,MATCH(Parâmetros!$D4,Volumes!$A$8:$A$13,0))*Parâmetros!$E4*((Parâmetros!$F4*INDEX(Premissas!$C$7:$C$9,MATCH(Parâmetros!$H4,Premissas!$B$7:$B$9,0))+Parâmetros!$G4*INDEX(Premissas!$D$7:$D$9,MATCH(Parâmetros!$H4,Premissas!$B$7:$B$9,0)))/1000000*Premissas!$B$2+Parâmetros!$I4),0) -> 63184.32 | L7: =IF(L$2>=Parâmetros!$K4,INDEX(Volumes!$K$8:$K$13,MATCH(Parâmetros!$D4,Volumes!$A$8:$A$13,0))*Parâmetros!$E4*((Parâmetros!$F4*INDEX(Premissas!$C$7:$C$9,MATCH(Parâmetros!$H4,Premissas!$B$7:$B$9,0))+Parâmetros!$G4*INDEX(Premissas!$D$7:$D$9,MATCH(Parâmetros!$H4,Premissas!$B$7:$B$9,0)))/1000000*Premissas!$B$2+Parâmetros!$I4),0) -> 87657.12 | M7: =IF(M$2>=Parâmetros!$K4,INDEX(Volumes!$L$8:$L$13,MATCH(Parâmetros!$D4,Volumes!$A$8:$A$13,0))*Parâmetros!$E4*((Parâmetros!$F4*INDEX(Premissas!$C$7:$C$9,MATCH(Parâmetros!$H4,Premissas!$B$7:$B$9,0))+Parâmetros!$G4*INDEX(Premissas!$D$7:$D$9,MATCH(Parâmetros!$H4,Premissas!$B$7:$B$9,0)))/1000000*Premissas!$B$2+Parâmetros!$I4),0) -> 11272.32 | N7: =IF(N$2>=Parâmetros!$K4,INDEX(Volumes!$M$8:$M$13,MATCH(Parâmetros!$D4,Volumes!$A$8:$A$13,0))*Parâmetros!$E4*((Parâmetros!$F4*INDEX(Premissas!$C$7:$C$9,MATCH(Parâmetros!$H4,Premissas!$B$7:$B$9,0))+Parâmetros!$G4*INDEX(Premissas!$D$7:$D$9,MATCH(Parâmetros!$H4,Premissas!$B$7:$B$9,0)))/1000000*Premissas!$B$2+Parâmetros!$I4),0) -> 29070.72 | O7: =IF(O$2>=Parâmetros!$K4,INDEX(Volumes!$N$8:$N$13,MATCH(Parâmetros!$D4,Volumes!$A$8:$A$13,0))*Parâmetros!$E4*((Parâmetros!$F4*INDEX(Premissas!$C$7:$C$9,MATCH(Parâmetros!$H4,Premissas!$B$7:$B$9,0))+Parâmetros!$G4*INDEX(Premissas!$D$7:$D$9,MATCH(Parâmetros!$H4,Premissas!$B$7:$B$9,0)))/1000000*Premissas!$B$2+Parâmetros!$I4),0) -> 110350.08 | P7: =SUM(D7:O7) -> 553678.56
A8: =Parâmetros!A5 -> P04 | B8: =Parâmetros!B5 -> App de escala de equipe | C8: =Parâmetros!C5 -> Lojas físicas | D8: =IF(D$2>=Parâmetros!$K5,INDEX(Volumes!$C$8:$C$13,MATCH(Parâmetros!$D5,Volumes!$A$8:$A$13,0))*Parâmetros!$E5*((Parâmetros!$F5*INDEX(Premissas!$C$7:$C$9,MATCH(Parâmetros!$H5,Premissas!$B$7:$B$9,0))+Parâmetros!$G5*INDEX(Premissas!$D$7:$D$9,MATCH(Parâmetros!$H5,Premissas!$B$7:$B$9,0)))/1000000*Premissas!$B$2+Parâmetros!$I5),0) -> 0 | E8: =IF(E$2>=Parâmetros!$K5,INDEX(Volumes!$D$8:$D$13,MATCH(Parâmetros!$D5,Volumes!$A$8:$A$13,0))*Parâmetros!$E5*((Parâmetros!$F5*INDEX(Premissas!$C$7:$C$9,MATCH(Parâmetros!$H5,Premissas!$B$7:$B$9,0))+Parâmetros!$G5*INDEX(Premissas!$D$7:$D$9,MATCH(Parâmetros!$H5,Premissas!$B$7:$B$9,0)))/1000000*Premissas!$B$2+Parâmetros!$I5),0) -> 0 | F8: =IF(F$2>=Parâmetros!$K5,INDEX(Volumes!$E$8:$E$13,MATCH(Parâmetros!$D5,Volumes!$A$8:$A$13,0))*Parâmetros!$E5*((Parâmetros!$F5*INDEX(Premissas!$C$7:$C$9,MATCH(Parâmetros!$H5,Premissas!$B$7:$B$9,0))+Parâmetros!$G5*INDEX(Premissas!$D$7:$D$9,MATCH(Parâmetros!$H5,Premissas!$B$7:$B$9,0)))/1000000*Premissas!$B$2+Parâmetros!$I5),0) -> 0 | G8: =IF(G$2>=Parâmetros!$K5,INDEX(Volumes!$F$8:$F$13,MATCH(Parâmetros!$D5,Volumes!$A$8:$A$13,0))*Parâmetros!$E5*((Parâmetros!$F5*INDEX(Premissas!$C$7:$C$9,MATCH(Parâmetros!$H5,Premissas!$B$7:$B$9,0))+Parâmetros!$G5*INDEX(Premissas!$D$7:$D$9,MATCH(Parâmetros!$H5,Premissas!$B$7:$B$9,0)))/1000000*Premissas!$B$2+Parâmetros!$I5),0) -> 0 | H8: =IF(H$2>=Parâmetros!$K5,INDEX(Volumes!$G$8:$G$13,MATCH(Parâmetros!$D5,Volumes!$A$8:$A$13,0))*Parâmetros!$E5*((Parâmetros!$F5*INDEX(Premissas!$C$7:$C$9,MATCH(Parâmetros!$H5,Premissas!$B$7:$B$9,0))+Parâmetros!$G5*INDEX(Premissas!$D$7:$D$9,MATCH(Parâmetros!$H5,Premissas!$B$7:$B$9,0)))/1000000*Premissas!$B$2+Parâmetros!$I5),0) -> 0 | I8: =IF(I$2>=Parâmetros!$K5,INDEX(Volumes!$H$8:$H$13,MATCH(Parâmetros!$D5,Volumes!$A$8:$A$13,0))*Parâmetros!$E5*((Parâmetros!$F5*INDEX(Premissas!$C$7:$C$9,MATCH(Parâmetros!$H5,Premissas!$B$7:$B$9,0))+Parâmetros!$G5*INDEX(Premissas!$D$7:$D$9,MATCH(Parâmetros!$H5,Premissas!$B$7:$B$9,0)))/1000000*Premissas!$B$2+Parâmetros!$I5),0) -> 0 | J8: =IF(J$2>=Parâmetros!$K5,INDEX(Volumes!$I$8:$I$13,MATCH(Parâmetros!$D5,Volumes!$A$8:$A$13,0))*Parâmetros!$E5*((Parâmetros!$F5*INDEX(Premissas!$C$7:$C$9,MATCH(Parâmetros!$H5,Premissas!$B$7:$B$9,0))+Parâmetros!$G5*INDEX(Premissas!$D$7:$D$9,MATCH(Parâmetros!$H5,Premissas!$B$7:$B$9,0)))/1000000*Premissas!$B$2+Parâmetros!$I5),0) -> 0 | K8: =IF(K$2>=Parâmetros!$K5,INDEX(Volumes!$J$8:$J$13,MATCH(Parâmetros!$D5,Volumes!$A$8:$A$13,0))*Parâmetros!$E5*((Parâmetros!$F5*INDEX(Premissas!$C$7:$C$9,MATCH(Parâmetros!$H5,Premissas!$B$7:$B$9,0))+Parâmetros!$G5*INDEX(Premissas!$D$7:$D$9,MATCH(Parâmetros!$H5,Premissas!$B$7:$B$9,0)))/1000000*Premissas!$B$2+Parâmetros!$I5),0) -> 0 | L8: =IF(L$2>=Parâmetros!$K5,INDEX(Volumes!$K$8:$K$13,MATCH(Parâmetros!$D5,Volumes!$A$8:$A$13,0))*Parâmetros!$E5*((Parâmetros!$F5*INDEX(Premissas!$C$7:$C$9,MATCH(Parâmetros!$H5,Premissas!$B$7:$B$9,0))+Parâmetros!$G5*INDEX(Premissas!$D$7:$D$9,MATCH(Parâmetros!$H5,Premissas!$B$7:$B$9,0)))/1000000*Premissas!$B$2+Parâmetros!$I5),0) -> 0 | M8: =IF(M$2>=Parâmetros!$K5,INDEX(Volumes!$L$8:$L$13,MATCH(Parâmetros!$D5,Volumes!$A$8:$A$13,0))*Parâmetros!$E5*((Parâmetros!$F5*INDEX(Premissas!$C$7:$C$9,MATCH(Parâmetros!$H5,Premissas!$B$7:$B$9,0))+Parâmetros!$G5*INDEX(Premissas!$D$7:$D$9,MATCH(Parâmetros!$H5,Premissas!$B$7:$B$9,0)))/1000000*Premissas!$B$2+Parâmetros!$I5),0) -> 0 | N8: =IF(N$2>=Parâmetros!$K5,INDEX(Volumes!$M$8:$M$13,MATCH(Parâmetros!$D5,Volumes!$A$8:$A$13,0))*Parâmetros!$E5*((Parâmetros!$F5*INDEX(Premissas!$C$7:$C$9,MATCH(Parâmetros!$H5,Premissas!$B$7:$B$9,0))+Parâmetros!$G5*INDEX(Premissas!$D$7:$D$9,MATCH(Parâmetros!$H5,Premissas!$B$7:$B$9,0)))/1000000*Premissas!$B$2+Parâmetros!$I5),0) -> 0 | O8: =IF(O$2>=Parâmetros!$K5,INDEX(Volumes!$N$8:$N$13,MATCH(Parâmetros!$D5,Volumes!$A$8:$A$13,0))*Parâmetros!$E5*((Parâmetros!$F5*INDEX(Premissas!$C$7:$C$9,MATCH(Parâmetros!$H5,Premissas!$B$7:$B$9,0))+Parâmetros!$G5*INDEX(Premissas!$D$7:$D$9,MATCH(Parâmetros!$H5,Premissas!$B$7:$B$9,0)))/1000000*Premissas!$B$2+Parâmetros!$I5),0) -> 0 | P8: =SUM(D8:O8) -> 0
A9: =Parâmetros!A6 -> P05 | B9: =Parâmetros!B6 -> Assistentes de IA de uso geral | C9: =Parâmetros!C6 -> Lojas físicas e áreas corporativas | D9: =IF(D$2>=Parâmetros!$K6,INDEX(Volumes!$C$8:$C$13,MATCH(Parâmetros!$D6,Volumes!$A$8:$A$13,0))*Parâmetros!$E6*((Parâmetros!$F6*INDEX(Premissas!$C$7:$C$9,MATCH(Parâmetros!$H6,Premissas!$B$7:$B$9,0))+Parâmetros!$G6*INDEX(Premissas!$D$7:$D$9,MATCH(Parâmetros!$H6,Premissas!$B$7:$B$9,0)))/1000000*Premissas!$B$2+Parâmetros!$I6),0) -> 13200 | E9: =IF(E$2>=Parâmetros!$K6,INDEX(Volumes!$D$8:$D$13,MATCH(Parâmetros!$D6,Volumes!$A$8:$A$13,0))*Parâmetros!$E6*((Parâmetros!$F6*INDEX(Premissas!$C$7:$C$9,MATCH(Parâmetros!$H6,Premissas!$B$7:$B$9,0))+Parâmetros!$G6*INDEX(Premissas!$D$7:$D$9,MATCH(Parâmetros!$H6,Premissas!$B$7:$B$9,0)))/1000000*Premissas!$B$2+Parâmetros!$I6),0) -> 16170 | F9: =IF(F$2>=Parâmetros!$K6,INDEX(Volumes!$E$8:$E$13,MATCH(Parâmetros!$D6,Volumes!$A$8:$A$13,0))*Parâmetros!$E6*((Parâmetros!$F6*INDEX(Premissas!$C$7:$C$9,MATCH(Parâmetros!$H6,Premissas!$B$7:$B$9,0))+Parâmetros!$G6*INDEX(Premissas!$D$7:$D$9,MATCH(Parâmetros!$H6,Premissas!$B$7:$B$9,0)))/1000000*Premissas!$B$2+Parâmetros!$I6),0) -> 19250 | G9: =IF(G$2>=Parâmetros!$K6,INDEX(Volumes!$F$8:$F$13,MATCH(Parâmetros!$D6,Volumes!$A$8:$A$13,0))*Parâmetros!$E6*((Parâmetros!$F6*INDEX(Premissas!$C$7:$C$9,MATCH(Parâmetros!$H6,Premissas!$B$7:$B$9,0))+Parâmetros!$G6*INDEX(Premissas!$D$7:$D$9,MATCH(Parâmetros!$H6,Premissas!$B$7:$B$9,0)))/1000000*Premissas!$B$2+Parâmetros!$I6),0) -> 22220 | H9: =IF(H$2>=Parâmetros!$K6,INDEX(Volumes!$G$8:$G$13,MATCH(Parâmetros!$D6,Volumes!$A$8:$A$13,0))*Parâmetros!$E6*((Parâmetros!$F6*INDEX(Premissas!$C$7:$C$9,MATCH(Parâmetros!$H6,Premissas!$B$7:$B$9,0))+Parâmetros!$G6*INDEX(Premissas!$D$7:$D$9,MATCH(Parâmetros!$H6,Premissas!$B$7:$B$9,0)))/1000000*Premissas!$B$2+Parâmetros!$I6),0) -> 25190 | I9: =IF(I$2>=Parâmetros!$K6,INDEX(Volumes!$H$8:$H$13,MATCH(Parâmetros!$D6,Volumes!$A$8:$A$13,0))*Parâmetros!$E6*((Parâmetros!$F6*INDEX(Premissas!$C$7:$C$9,MATCH(Parâmetros!$H6,Premissas!$B$7:$B$9,0))+Parâmetros!$G6*INDEX(Premissas!$D$7:$D$9,MATCH(Parâmetros!$H6,Premissas!$B$7:$B$9,0)))/1000000*Premissas!$B$2+Parâmetros!$I6),0) -> 28160 | J9: =IF(J$2>=Parâmetros!$K6,INDEX(Volumes!$I$8:$I$13,MATCH(Parâmetros!$D6,Volumes!$A$8:$A$13,0))*Parâmetros!$E6*((Parâmetros!$F6*INDEX(Premissas!$C$7:$C$9,MATCH(Parâmetros!$H6,Premissas!$B$7:$B$9,0))+Parâmetros!$G6*INDEX(Premissas!$D$7:$D$9,MATCH(Parâmetros!$H6,Premissas!$B$7:$B$9,0)))/1000000*Premissas!$B$2+Parâmetros!$I6),0) -> 31240 | K9: =IF(K$2>=Parâmetros!$K6,INDEX(Volumes!$J$8:$J$13,MATCH(Parâmetros!$D6,Volumes!$A$8:$A$13,0))*Parâmetros!$E6*((Parâmetros!$F6*INDEX(Premissas!$C$7:$C$9,MATCH(Parâmetros!$H6,Premissas!$B$7:$B$9,0))+Parâmetros!$G6*INDEX(Premissas!$D$7:$D$9,MATCH(Parâmetros!$H6,Premissas!$B$7:$B$9,0)))/1000000*Premissas!$B$2+Parâmetros!$I6),0) -> 34210 | L9: =IF(L$2>=Parâmetros!$K6,INDEX(Volumes!$K$8:$K$13,MATCH(Parâmetros!$D6,Volumes!$A$8:$A$13,0))*Parâmetros!$E6*((Parâmetros!$F6*INDEX(Premissas!$C$7:$C$9,MATCH(Parâmetros!$H6,Premissas!$B$7:$B$9,0))+Parâmetros!$G6*INDEX(Premissas!$D$7:$D$9,MATCH(Parâmetros!$H6,Premissas!$B$7:$B$9,0)))/1000000*Premissas!$B$2+Parâmetros!$I6),0) -> 37180 | M9: =IF(M$2>=Parâmetros!$K6,INDEX(Volumes!$L$8:$L$13,MATCH(Parâmetros!$D6,Volumes!$A$8:$A$13,0))*Parâmetros!$E6*((Parâmetros!$F6*INDEX(Premissas!$C$7:$C$9,MATCH(Parâmetros!$H6,Premissas!$B$7:$B$9,0))+Parâmetros!$G6*INDEX(Premissas!$D$7:$D$9,MATCH(Parâmetros!$H6,Premissas!$B$7:$B$9,0)))/1000000*Premissas!$B$2+Parâmetros!$I6),0) -> 40150 | N9: =IF(N$2>=Parâmetros!$K6,INDEX(Volumes!$M$8:$M$13,MATCH(Parâmetros!$D6,Volumes!$A$8:$A$13,0))*Parâmetros!$E6*((Parâmetros!$F6*INDEX(Premissas!$C$7:$C$9,MATCH(Parâmetros!$H6,Premissas!$B$7:$B$9,0))+Parâmetros!$G6*INDEX(Premissas!$D$7:$D$9,MATCH(Parâmetros!$H6,Premissas!$B$7:$B$9,0)))/1000000*Premissas!$B$2+Parâmetros!$I6),0) -> 43230 | O9: =IF(O$2>=Parâmetros!$K6,INDEX(Volumes!$N$8:$N$13,MATCH(Parâmetros!$D6,Volumes!$A$8:$A$13,0))*Parâmetros!$E6*((Parâmetros!$F6*INDEX(Premissas!$C$7:$C$9,MATCH(Parâmetros!$H6,Premissas!$B$7:$B$9,0))+Parâmetros!$G6*INDEX(Premissas!$D$7:$D$9,MATCH(Parâmetros!$H6,Premissas!$B$7:$B$9,0)))/1000000*Premissas!$B$2+Parâmetros!$I6),0) -> 46200 | P9: =SUM(D9:O9) -> 356400
A10: =Parâmetros!A7 -> P06 | B10: =Parâmetros!B7 -> Modelo de crédito a sellers | C10: =Parâmetros!C7 -> Serviços financeiros | D10: =IF(D$2>=Parâmetros!$K7,INDEX(Volumes!$C$8:$C$13,MATCH(Parâmetros!$D7,Volumes!$A$8:$A$13,0))*Parâmetros!$E7*((Parâmetros!$F7*INDEX(Premissas!$C$7:$C$9,MATCH(Parâmetros!$H7,Premissas!$B$7:$B$9,0))+Parâmetros!$G7*INDEX(Premissas!$D$7:$D$9,MATCH(Parâmetros!$H7,Premissas!$B$7:$B$9,0)))/1000000*Premissas!$B$2+Parâmetros!$I7),0) -> 0 | E10: =IF(E$2>=Parâmetros!$K7,INDEX(Volumes!$D$8:$D$13,MATCH(Parâmetros!$D7,Volumes!$A$8:$A$13,0))*Parâmetros!$E7*((Parâmetros!$F7*INDEX(Premissas!$C$7:$C$9,MATCH(Parâmetros!$H7,Premissas!$B$7:$B$9,0))+Parâmetros!$G7*INDEX(Premissas!$D$7:$D$9,MATCH(Parâmetros!$H7,Premissas!$B$7:$B$9,0)))/1000000*Premissas!$B$2+Parâmetros!$I7),0) -> 0 | F10: =IF(F$2>=Parâmetros!$K7,INDEX(Volumes!$E$8:$E$13,MATCH(Parâmetros!$D7,Volumes!$A$8:$A$13,0))*Parâmetros!$E7*((Parâmetros!$F7*INDEX(Premissas!$C$7:$C$9,MATCH(Parâmetros!$H7,Premissas!$B$7:$B$9,0))+Parâmetros!$G7*INDEX(Premissas!$D$7:$D$9,MATCH(Parâmetros!$H7,Premissas!$B$7:$B$9,0)))/1000000*Premissas!$B$2+Parâmetros!$I7),0) -> 0 | G10: =IF(G$2>=Parâmetros!$K7,INDEX(Volumes!$F$8:$F$13,MATCH(Parâmetros!$D7,Volumes!$A$8:$A$13,0))*Parâmetros!$E7*((Parâmetros!$F7*INDEX(Premissas!$C$7:$C$9,MATCH(Parâmetros!$H7,Premissas!$B$7:$B$9,0))+Parâmetros!$G7*INDEX(Premissas!$D$7:$D$9,MATCH(Parâmetros!$H7,Premissas!$B$7:$B$9,0)))/1000000*Premissas!$B$2+Parâmetros!$I7),0) -> 0 | H10: =IF(H$2>=Parâmetros!$K7,INDEX(Volumes!$G$8:$G$13,MATCH(Parâmetros!$D7,Volumes!$A$8:$A$13,0))*Parâmetros!$E7*((Parâmetros!$F7*INDEX(Premissas!$C$7:$C$9,MATCH(Parâmetros!$H7,Premissas!$B$7:$B$9,0))+Parâmetros!$G7*INDEX(Premissas!$D$7:$D$9,MATCH(Parâmetros!$H7,Premissas!$B$7:$B$9,0)))/1000000*Premissas!$B$2+Parâmetros!$I7),0) -> 0 | I10: =IF(I$2>=Parâmetros!$K7,INDEX(Volumes!$H$8:$H$13,MATCH(Parâmetros!$D7,Volumes!$A$8:$A$13,0))*Parâmetros!$E7*((Parâmetros!$F7*INDEX(Premissas!$C$7:$C$9,MATCH(Parâmetros!$H7,Premissas!$B$7:$B$9,0))+Parâmetros!$G7*INDEX(Premissas!$D$7:$D$9,MATCH(Parâmetros!$H7,Premissas!$B$7:$B$9,0)))/1000000*Premissas!$B$2+Parâmetros!$I7),0) -> 0 | J10: =IF(J$2>=Parâmetros!$K7,INDEX(Volumes!$I$8:$I$13,MATCH(Parâmetros!$D7,Volumes!$A$8:$A$13,0))*Parâmetros!$E7*((Parâmetros!$F7*INDEX(Premissas!$C$7:$C$9,MATCH(Parâmetros!$H7,Premissas!$B$7:$B$9,0))+Parâmetros!$G7*INDEX(Premissas!$D$7:$D$9,MATCH(Parâmetros!$H7,Premissas!$B$7:$B$9,0)))/1000000*Premissas!$B$2+Parâmetros!$I7),0) -> 0 | K10: =IF(K$2>=Parâmetros!$K7,INDEX(Volumes!$J$8:$J$13,MATCH(Parâmetros!$D7,Volumes!$A$8:$A$13,0))*Parâmetros!$E7*((Parâmetros!$F7*INDEX(Premissas!$C$7:$C$9,MATCH(Parâmetros!$H7,Premissas!$B$7:$B$9,0))+Parâmetros!$G7*INDEX(Premissas!$D$7:$D$9,MATCH(Parâmetros!$H7,Premissas!$B$7:$B$9,0)))/1000000*Premissas!$B$2+Parâmetros!$I7),0) -> 0 | L10: =IF(L$2>=Parâmetros!$K7,INDEX(Volumes!$K$8:$K$13,MATCH(Parâmetros!$D7,Volumes!$A$8:$A$13,0))*Parâmetros!$E7*((Parâmetros!$F7*INDEX(Premissas!$C$7:$C$9,MATCH(Parâmetros!$H7,Premissas!$B$7:$B$9,0))+Parâmetros!$G7*INDEX(Premissas!$D$7:$D$9,MATCH(Parâmetros!$H7,Premissas!$B$7:$B$9,0)))/1000000*Premissas!$B$2+Parâmetros!$I7),0) -> 0 | M10: =IF(M$2>=Parâmetros!$K7,INDEX(Volumes!$L$8:$L$13,MATCH(Parâmetros!$D7,Volumes!$A$8:$A$13,0))*Parâmetros!$E7*((Parâmetros!$F7*INDEX(Premissas!$C$7:$C$9,MATCH(Parâmetros!$H7,Premissas!$B$7:$B$9,0))+Parâmetros!$G7*INDEX(Premissas!$D$7:$D$9,MATCH(Parâmetros!$H7,Premissas!$B$7:$B$9,0)))/1000000*Premissas!$B$2+Parâmetros!$I7),0) -> 0 | N10: =IF(N$2>=Parâmetros!$K7,INDEX(Volumes!$M$8:$M$13,MATCH(Parâmetros!$D7,Volumes!$A$8:$A$13,0))*Parâmetros!$E7*((Parâmetros!$F7*INDEX(Premissas!$C$7:$C$9,MATCH(Parâmetros!$H7,Premissas!$B$7:$B$9,0))+Parâmetros!$G7*INDEX(Premissas!$D$7:$D$9,MATCH(Parâmetros!$H7,Premissas!$B$7:$B$9,0)))/1000000*Premissas!$B$2+Parâmetros!$I7),0) -> 0 | O10: =IF(O$2>=Parâmetros!$K7,INDEX(Volumes!$N$8:$N$13,MATCH(Parâmetros!$D7,Volumes!$A$8:$A$13,0))*Parâmetros!$E7*((Parâmetros!$F7*INDEX(Premissas!$C$7:$C$9,MATCH(Parâmetros!$H7,Premissas!$B$7:$B$9,0))+Parâmetros!$G7*INDEX(Premissas!$D$7:$D$9,MATCH(Parâmetros!$H7,Premissas!$B$7:$B$9,0)))/1000000*Premissas!$B$2+Parâmetros!$I7),0) -> 0 | P10: =SUM(D10:O10) -> 0
A11: =Parâmetros!A8 -> P07 | B11: =Parâmetros!B8 -> Antifraude de pagamentos | C11: =Parâmetros!C8 -> Serviços financeiros | D11: =IF(D$2>=Parâmetros!$K8,INDEX(Volumes!$C$8:$C$13,MATCH(Parâmetros!$D8,Volumes!$A$8:$A$13,0))*Parâmetros!$E8*((Parâmetros!$F8*INDEX(Premissas!$C$7:$C$9,MATCH(Parâmetros!$H8,Premissas!$B$7:$B$9,0))+Parâmetros!$G8*INDEX(Premissas!$D$7:$D$9,MATCH(Parâmetros!$H8,Premissas!$B$7:$B$9,0)))/1000000*Premissas!$B$2+Parâmetros!$I8),0) -> 0 | E11: =IF(E$2>=Parâmetros!$K8,INDEX(Volumes!$D$8:$D$13,MATCH(Parâmetros!$D8,Volumes!$A$8:$A$13,0))*Parâmetros!$E8*((Parâmetros!$F8*INDEX(Premissas!$C$7:$C$9,MATCH(Parâmetros!$H8,Premissas!$B$7:$B$9,0))+Parâmetros!$G8*INDEX(Premissas!$D$7:$D$9,MATCH(Parâmetros!$H8,Premissas!$B$7:$B$9,0)))/1000000*Premissas!$B$2+Parâmetros!$I8),0) -> 0 | F11: =IF(F$2>=Parâmetros!$K8,INDEX(Volumes!$E$8:$E$13,MATCH(Parâmetros!$D8,Volumes!$A$8:$A$13,0))*Parâmetros!$E8*((Parâmetros!$F8*INDEX(Premissas!$C$7:$C$9,MATCH(Parâmetros!$H8,Premissas!$B$7:$B$9,0))+Parâmetros!$G8*INDEX(Premissas!$D$7:$D$9,MATCH(Parâmetros!$H8,Premissas!$B$7:$B$9,0)))/1000000*Premissas!$B$2+Parâmetros!$I8),0) -> 0 | G11: =IF(G$2>=Parâmetros!$K8,INDEX(Volumes!$F$8:$F$13,MATCH(Parâmetros!$D8,Volumes!$A$8:$A$13,0))*Parâmetros!$E8*((Parâmetros!$F8*INDEX(Premissas!$C$7:$C$9,MATCH(Parâmetros!$H8,Premissas!$B$7:$B$9,0))+Parâmetros!$G8*INDEX(Premissas!$D$7:$D$9,MATCH(Parâmetros!$H8,Premissas!$B$7:$B$9,0)))/1000000*Premissas!$B$2+Parâmetros!$I8),0) -> 0 | H11: =IF(H$2>=Parâmetros!$K8,INDEX(Volumes!$G$8:$G$13,MATCH(Parâmetros!$D8,Volumes!$A$8:$A$13,0))*Parâmetros!$E8*((Parâmetros!$F8*INDEX(Premissas!$C$7:$C$9,MATCH(Parâmetros!$H8,Premissas!$B$7:$B$9,0))+Parâmetros!$G8*INDEX(Premissas!$D$7:$D$9,MATCH(Parâmetros!$H8,Premissas!$B$7:$B$9,0)))/1000000*Premissas!$B$2+Parâmetros!$I8),0) -> 0 | I11: =IF(I$2>=Parâmetros!$K8,INDEX(Volumes!$H$8:$H$13,MATCH(Parâmetros!$D8,Volumes!$A$8:$A$13,0))*Parâmetros!$E8*((Parâmetros!$F8*INDEX(Premissas!$C$7:$C$9,MATCH(Parâmetros!$H8,Premissas!$B$7:$B$9,0))+Parâmetros!$G8*INDEX(Premissas!$D$7:$D$9,MATCH(Parâmetros!$H8,Premissas!$B$7:$B$9,0)))/1000000*Premissas!$B$2+Parâmetros!$I8),0) -> 0 | J11: =IF(J$2>=Parâmetros!$K8,INDEX(Volumes!$I$8:$I$13,MATCH(Parâmetros!$D8,Volumes!$A$8:$A$13,0))*Parâmetros!$E8*((Parâmetros!$F8*INDEX(Premissas!$C$7:$C$9,MATCH(Parâmetros!$H8,Premissas!$B$7:$B$9,0))+Parâmetros!$G8*INDEX(Premissas!$D$7:$D$9,MATCH(Parâmetros!$H8,Premissas!$B$7:$B$9,0)))/1000000*Premissas!$B$2+Parâmetros!$I8),0) -> 0 | K11: =IF(K$2>=Parâmetros!$K8,INDEX(Volumes!$J$8:$J$13,MATCH(Parâmetros!$D8,Volumes!$A$8:$A$13,0))*Parâmetros!$E8*((Parâmetros!$F8*INDEX(Premissas!$C$7:$C$9,MATCH(Parâmetros!$H8,Premissas!$B$7:$B$9,0))+Parâmetros!$G8*INDEX(Premissas!$D$7:$D$9,MATCH(Parâmetros!$H8,Premissas!$B$7:$B$9,0)))/1000000*Premissas!$B$2+Parâmetros!$I8),0) -> 0 | L11: =IF(L$2>=Parâmetros!$K8,INDEX(Volumes!$K$8:$K$13,MATCH(Parâmetros!$D8,Volumes!$A$8:$A$13,0))*Parâmetros!$E8*((Parâmetros!$F8*INDEX(Premissas!$C$7:$C$9,MATCH(Parâmetros!$H8,Premissas!$B$7:$B$9,0))+Parâmetros!$G8*INDEX(Premissas!$D$7:$D$9,MATCH(Parâmetros!$H8,Premissas!$B$7:$B$9,0)))/1000000*Premissas!$B$2+Parâmetros!$I8),0) -> 0 | M11: =IF(M$2>=Parâmetros!$K8,INDEX(Volumes!$L$8:$L$13,MATCH(Parâmetros!$D8,Volumes!$A$8:$A$13,0))*Parâmetros!$E8*((Parâmetros!$F8*INDEX(Premissas!$C$7:$C$9,MATCH(Parâmetros!$H8,Premissas!$B$7:$B$9,0))+Parâmetros!$G8*INDEX(Premissas!$D$7:$D$9,MATCH(Parâmetros!$H8,Premissas!$B$7:$B$9,0)))/1000000*Premissas!$B$2+Parâmetros!$I8),0) -> 0 | N11: =IF(N$2>=Parâmetros!$K8,INDEX(Volumes!$M$8:$M$13,MATCH(Parâmetros!$D8,Volumes!$A$8:$A$13,0))*Parâmetros!$E8*((Parâmetros!$F8*INDEX(Premissas!$C$7:$C$9,MATCH(Parâmetros!$H8,Premissas!$B$7:$B$9,0))+Parâmetros!$G8*INDEX(Premissas!$D$7:$D$9,MATCH(Parâmetros!$H8,Premissas!$B$7:$B$9,0)))/1000000*Premissas!$B$2+Parâmetros!$I8),0) -> 0 | O11: =IF(O$2>=Parâmetros!$K8,INDEX(Volumes!$N$8:$N$13,MATCH(Parâmetros!$D8,Volumes!$A$8:$A$13,0))*Parâmetros!$E8*((Parâmetros!$F8*INDEX(Premissas!$C$7:$C$9,MATCH(Parâmetros!$H8,Premissas!$B$7:$B$9,0))+Parâmetros!$G8*INDEX(Premissas!$D$7:$D$9,MATCH(Parâmetros!$H8,Premissas!$B$7:$B$9,0)))/1000000*Premissas!$B$2+Parâmetros!$I8),0) -> 0 | P11: =SUM(D11:O11) -> 0
A12: =Parâmetros!A9 -> P08 | B12: =Parâmetros!B9 -> Assistente interno de RH e políticas | C12: =Parâmetros!C9 -> Corporativo | D12: =IF(D$2>=Parâmetros!$K9,INDEX(Volumes!$C$8:$C$13,MATCH(Parâmetros!$D9,Volumes!$A$8:$A$13,0))*Parâmetros!$E9*((Parâmetros!$F9*INDEX(Premissas!$C$7:$C$9,MATCH(Parâmetros!$H9,Premissas!$B$7:$B$9,0))+Parâmetros!$G9*INDEX(Premissas!$D$7:$D$9,MATCH(Parâmetros!$H9,Premissas!$B$7:$B$9,0)))/1000000*Premissas!$B$2+Parâmetros!$I9),0) -> 0 | E12: =IF(E$2>=Parâmetros!$K9,INDEX(Volumes!$D$8:$D$13,MATCH(Parâmetros!$D9,Volumes!$A$8:$A$13,0))*Parâmetros!$E9*((Parâmetros!$F9*INDEX(Premissas!$C$7:$C$9,MATCH(Parâmetros!$H9,Premissas!$B$7:$B$9,0))+Parâmetros!$G9*INDEX(Premissas!$D$7:$D$9,MATCH(Parâmetros!$H9,Premissas!$B$7:$B$9,0)))/1000000*Premissas!$B$2+Parâmetros!$I9),0) -> 0 | F12: =IF(F$2>=Parâmetros!$K9,INDEX(Volumes!$E$8:$E$13,MATCH(Parâmetros!$D9,Volumes!$A$8:$A$13,0))*Parâmetros!$E9*((Parâmetros!$F9*INDEX(Premissas!$C$7:$C$9,MATCH(Parâmetros!$H9,Premissas!$B$7:$B$9,0))+Parâmetros!$G9*INDEX(Premissas!$D$7:$D$9,MATCH(Parâmetros!$H9,Premissas!$B$7:$B$9,0)))/1000000*Premissas!$B$2+Parâmetros!$I9),0) -> 0 | G12: =IF(G$2>=Parâmetros!$K9,INDEX(Volumes!$F$8:$F$13,MATCH(Parâmetros!$D9,Volumes!$A$8:$A$13,0))*Parâmetros!$E9*((Parâmetros!$F9*INDEX(Premissas!$C$7:$C$9,MATCH(Parâmetros!$H9,Premissas!$B$7:$B$9,0))+Parâmetros!$G9*INDEX(Premissas!$D$7:$D$9,MATCH(Parâmetros!$H9,Premissas!$B$7:$B$9,0)))/1000000*Premissas!$B$2+Parâmetros!$I9),0) -> 0 | H12: =IF(H$2>=Parâmetros!$K9,INDEX(Volumes!$G$8:$G$13,MATCH(Parâmetros!$D9,Volumes!$A$8:$A$13,0))*Parâmetros!$E9*((Parâmetros!$F9*INDEX(Premissas!$C$7:$C$9,MATCH(Parâmetros!$H9,Premissas!$B$7:$B$9,0))+Parâmetros!$G9*INDEX(Premissas!$D$7:$D$9,MATCH(Parâmetros!$H9,Premissas!$B$7:$B$9,0)))/1000000*Premissas!$B$2+Parâmetros!$I9),0) -> 0 | I12: =IF(I$2>=Parâmetros!$K9,INDEX(Volumes!$H$8:$H$13,MATCH(Parâmetros!$D9,Volumes!$A$8:$A$13,0))*Parâmetros!$E9*((Parâmetros!$F9*INDEX(Premissas!$C$7:$C$9,MATCH(Parâmetros!$H9,Premissas!$B$7:$B$9,0))+Parâmetros!$G9*INDEX(Premissas!$D$7:$D$9,MATCH(Parâmetros!$H9,Premissas!$B$7:$B$9,0)))/1000000*Premissas!$B$2+Parâmetros!$I9),0) -> 0 | J12: =IF(J$2>=Parâmetros!$K9,INDEX(Volumes!$I$8:$I$13,MATCH(Parâmetros!$D9,Volumes!$A$8:$A$13,0))*Parâmetros!$E9*((Parâmetros!$F9*INDEX(Premissas!$C$7:$C$9,MATCH(Parâmetros!$H9,Premissas!$B$7:$B$9,0))+Parâmetros!$G9*INDEX(Premissas!$D$7:$D$9,MATCH(Parâmetros!$H9,Premissas!$B$7:$B$9,0)))/1000000*Premissas!$B$2+Parâmetros!$I9),0) -> 0 | K12: =IF(K$2>=Parâmetros!$K9,INDEX(Volumes!$J$8:$J$13,MATCH(Parâmetros!$D9,Volumes!$A$8:$A$13,0))*Parâmetros!$E9*((Parâmetros!$F9*INDEX(Premissas!$C$7:$C$9,MATCH(Parâmetros!$H9,Premissas!$B$7:$B$9,0))+Parâmetros!$G9*INDEX(Premissas!$D$7:$D$9,MATCH(Parâmetros!$H9,Premissas!$B$7:$B$9,0)))/1000000*Premissas!$B$2+Parâmetros!$I9),0) -> 0 | L12: =IF(L$2>=Parâmetros!$K9,INDEX(Volumes!$K$8:$K$13,MATCH(Parâmetros!$D9,Volumes!$A$8:$A$13,0))*Parâmetros!$E9*((Parâmetros!$F9*INDEX(Premissas!$C$7:$C$9,MATCH(Parâmetros!$H9,Premissas!$B$7:$B$9,0))+Parâmetros!$G9*INDEX(Premissas!$D$7:$D$9,MATCH(Parâmetros!$H9,Premissas!$B$7:$B$9,0)))/1000000*Premissas!$B$2+Parâmetros!$I9),0) -> 5356 | M12: =IF(M$2>=Parâmetros!$K9,INDEX(Volumes!$L$8:$L$13,MATCH(Parâmetros!$D9,Volumes!$A$8:$A$13,0))*Parâmetros!$E9*((Parâmetros!$F9*INDEX(Premissas!$C$7:$C$9,MATCH(Parâmetros!$H9,Premissas!$B$7:$B$9,0))+Parâmetros!$G9*INDEX(Premissas!$D$7:$D$9,MATCH(Parâmetros!$H9,Premissas!$B$7:$B$9,0)))/1000000*Premissas!$B$2+Parâmetros!$I9),0) -> 5356 | N12: =IF(N$2>=Parâmetros!$K9,INDEX(Volumes!$M$8:$M$13,MATCH(Parâmetros!$D9,Volumes!$A$8:$A$13,0))*Parâmetros!$E9*((Parâmetros!$F9*INDEX(Premissas!$C$7:$C$9,MATCH(Parâmetros!$H9,Premissas!$B$7:$B$9,0))+Parâmetros!$G9*INDEX(Premissas!$D$7:$D$9,MATCH(Parâmetros!$H9,Premissas!$B$7:$B$9,0)))/1000000*Premissas!$B$2+Parâmetros!$I9),0) -> 5356 | O12: =IF(O$2>=Parâmetros!$K9,INDEX(Volumes!$N$8:$N$13,MATCH(Parâmetros!$D9,Volumes!$A$8:$A$13,0))*Parâmetros!$E9*((Parâmetros!$F9*INDEX(Premissas!$C$7:$C$9,MATCH(Parâmetros!$H9,Premissas!$B$7:$B$9,0))+Parâmetros!$G9*INDEX(Premissas!$D$7:$D$9,MATCH(Parâmetros!$H9,Premissas!$B$7:$B$9,0)))/1000000*Premissas!$B$2+Parâmetros!$I9),0) -> 5356 | P12: =SUM(D12:O12) -> 21424
A13: =Parâmetros!A10 -> X1 | B13: =Parâmetros!B10 -> Recursos de nuvem sem piloto atribuído | C13: =Parâmetros!C10 -> Não atribuído | D13: =IF(D$2>=Parâmetros!$K10,INDEX(Volumes!$C$8:$C$13,MATCH(Parâmetros!$D10,Volumes!$A$8:$A$13,0))*Parâmetros!$E10*((Parâmetros!$F10*INDEX(Premissas!$C$7:$C$9,MATCH(Parâmetros!$H10,Premissas!$B$7:$B$9,0))+Parâmetros!$G10*INDEX(Premissas!$D$7:$D$9,MATCH(Parâmetros!$H10,Premissas!$B$7:$B$9,0)))/1000000*Premissas!$B$2+Parâmetros!$I10),0) -> 0 | E13: =IF(E$2>=Parâmetros!$K10,INDEX(Volumes!$D$8:$D$13,MATCH(Parâmetros!$D10,Volumes!$A$8:$A$13,0))*Parâmetros!$E10*((Parâmetros!$F10*INDEX(Premissas!$C$7:$C$9,MATCH(Parâmetros!$H10,Premissas!$B$7:$B$9,0))+Parâmetros!$G10*INDEX(Premissas!$D$7:$D$9,MATCH(Parâmetros!$H10,Premissas!$B$7:$B$9,0)))/1000000*Premissas!$B$2+Parâmetros!$I10),0) -> 0 | F13: =IF(F$2>=Parâmetros!$K10,INDEX(Volumes!$E$8:$E$13,MATCH(Parâmetros!$D10,Volumes!$A$8:$A$13,0))*Parâmetros!$E10*((Parâmetros!$F10*INDEX(Premissas!$C$7:$C$9,MATCH(Parâmetros!$H10,Premissas!$B$7:$B$9,0))+Parâmetros!$G10*INDEX(Premissas!$D$7:$D$9,MATCH(Parâmetros!$H10,Premissas!$B$7:$B$9,0)))/1000000*Premissas!$B$2+Parâmetros!$I10),0) -> 0 | G13: =IF(G$2>=Parâmetros!$K10,INDEX(Volumes!$F$8:$F$13,MATCH(Parâmetros!$D10,Volumes!$A$8:$A$13,0))*Parâmetros!$E10*((Parâmetros!$F10*INDEX(Premissas!$C$7:$C$9,MATCH(Parâmetros!$H10,Premissas!$B$7:$B$9,0))+Parâmetros!$G10*INDEX(Premissas!$D$7:$D$9,MATCH(Parâmetros!$H10,Premissas!$B$7:$B$9,0)))/1000000*Premissas!$B$2+Parâmetros!$I10),0) -> 0 | H13: =IF(H$2>=Parâmetros!$K10,INDEX(Volumes!$G$8:$G$13,MATCH(Parâmetros!$D10,Volumes!$A$8:$A$13,0))*Parâmetros!$E10*((Parâmetros!$F10*INDEX(Premissas!$C$7:$C$9,MATCH(Parâmetros!$H10,Premissas!$B$7:$B$9,0))+Parâmetros!$G10*INDEX(Premissas!$D$7:$D$9,MATCH(Parâmetros!$H10,Premissas!$B$7:$B$9,0)))/1000000*Premissas!$B$2+Parâmetros!$I10),0) -> 0 | I13: =IF(I$2>=Parâmetros!$K10,INDEX(Volumes!$H$8:$H$13,MATCH(Parâmetros!$D10,Volumes!$A$8:$A$13,0))*Parâmetros!$E10*((Parâmetros!$F10*INDEX(Premissas!$C$7:$C$9,MATCH(Parâmetros!$H10,Premissas!$B$7:$B$9,0))+Parâmetros!$G10*INDEX(Premissas!$D$7:$D$9,MATCH(Parâmetros!$H10,Premissas!$B$7:$B$9,0)))/1000000*Premissas!$B$2+Parâmetros!$I10),0) -> 0 | J13: =IF(J$2>=Parâmetros!$K10,INDEX(Volumes!$I$8:$I$13,MATCH(Parâmetros!$D10,Volumes!$A$8:$A$13,0))*Parâmetros!$E10*((Parâmetros!$F10*INDEX(Premissas!$C$7:$C$9,MATCH(Parâmetros!$H10,Premissas!$B$7:$B$9,0))+Parâmetros!$G10*INDEX(Premissas!$D$7:$D$9,MATCH(Parâmetros!$H10,Premissas!$B$7:$B$9,0)))/1000000*Premissas!$B$2+Parâmetros!$I10),0) -> 0 | K13: =IF(K$2>=Parâmetros!$K10,INDEX(Volumes!$J$8:$J$13,MATCH(Parâmetros!$D10,Volumes!$A$8:$A$13,0))*Parâmetros!$E10*((Parâmetros!$F10*INDEX(Premissas!$C$7:$C$9,MATCH(Parâmetros!$H10,Premissas!$B$7:$B$9,0))+Parâmetros!$G10*INDEX(Premissas!$D$7:$D$9,MATCH(Parâmetros!$H10,Premissas!$B$7:$B$9,0)))/1000000*Premissas!$B$2+Parâmetros!$I10),0) -> 0 | L13: =IF(L$2>=Parâmetros!$K10,INDEX(Volumes!$K$8:$K$13,MATCH(Parâmetros!$D10,Volumes!$A$8:$A$13,0))*Parâmetros!$E10*((Parâmetros!$F10*INDEX(Premissas!$C$7:$C$9,MATCH(Parâmetros!$H10,Premissas!$B$7:$B$9,0))+Parâmetros!$G10*INDEX(Premissas!$D$7:$D$9,MATCH(Parâmetros!$H10,Premissas!$B$7:$B$9,0)))/1000000*Premissas!$B$2+Parâmetros!$I10),0) -> 0 | M13: =IF(M$2>=Parâmetros!$K10,INDEX(Volumes!$L$8:$L$13,MATCH(Parâmetros!$D10,Volumes!$A$8:$A$13,0))*Parâmetros!$E10*((Parâmetros!$F10*INDEX(Premissas!$C$7:$C$9,MATCH(Parâmetros!$H10,Premissas!$B$7:$B$9,0))+Parâmetros!$G10*INDEX(Premissas!$D$7:$D$9,MATCH(Parâmetros!$H10,Premissas!$B$7:$B$9,0)))/1000000*Premissas!$B$2+Parâmetros!$I10),0) -> 0 | N13: =IF(N$2>=Parâmetros!$K10,INDEX(Volumes!$M$8:$M$13,MATCH(Parâmetros!$D10,Volumes!$A$8:$A$13,0))*Parâmetros!$E10*((Parâmetros!$F10*INDEX(Premissas!$C$7:$C$9,MATCH(Parâmetros!$H10,Premissas!$B$7:$B$9,0))+Parâmetros!$G10*INDEX(Premissas!$D$7:$D$9,MATCH(Parâmetros!$H10,Premissas!$B$7:$B$9,0)))/1000000*Premissas!$B$2+Parâmetros!$I10),0) -> 0 | O13: =IF(O$2>=Parâmetros!$K10,INDEX(Volumes!$N$8:$N$13,MATCH(Parâmetros!$D10,Volumes!$A$8:$A$13,0))*Parâmetros!$E10*((Parâmetros!$F10*INDEX(Premissas!$C$7:$C$9,MATCH(Parâmetros!$H10,Premissas!$B$7:$B$9,0))+Parâmetros!$G10*INDEX(Premissas!$D$7:$D$9,MATCH(Parâmetros!$H10,Premissas!$B$7:$B$9,0)))/1000000*Premissas!$B$2+Parâmetros!$I10),0) -> 0 | P13: =SUM(D13:O13) -> 0
B14: Total | D14: =SUM(D5:D13) -> 13200 | E14: =SUM(E5:E13) -> 16170 | F14: =SUM(F5:F13) -> 25043.75 | G14: =SUM(G5:G13) -> 28013.75 | H14: =SUM(H5:H13) -> 30983.75 | I14: =SUM(I5:I13) -> 117211.82 | J14: =SUM(J5:J13) -> 386711.56 | K14: =SUM(K5:K13) -> 191149.19 | ... P14: =SUM(P5:P13) -> 1599106.5
A17: Custo fixo (infraestrutura, licenças e contratos)
A18: ID | B18: Piloto | C18: Unidade | D18: set/25 | E18: out/25 | F18: nov/25 | G18: dez/25 | H18: jan/26 | I18: fev/26 | J18: mar/26 | K18: abr/26 | L18: mai/26 | M18: jun/26 | N18: jul/26 | O18: ago/26 | P18: Total 12 meses
A19: =Parâmetros!A2 -> P01 | B19: =Parâmetros!B2 -> Agente de SAC com RAG | C19: =Parâmetros!C2 -> Marketplace e e-commerce | D19: =IF(D$2>=Parâmetros!$K2,Parâmetros!$J2,0) -> 0 | E19: =IF(E$2>=Parâmetros!$K2,Parâmetros!$J2,0) -> 0 | F19: =IF(F$2>=Parâmetros!$K2,Parâmetros!$J2,0) -> 0 | G19: =IF(G$2>=Parâmetros!$K2,Parâmetros!$J2,0) -> 0 | H19: =IF(H$2>=Parâmetros!$K2,Parâmetros!$J2,0) -> 0 | I19: =IF(I$2>=Parâmetros!$K2,Parâmetros!$J2,0) -> 12000 | J19: =IF(J$2>=Parâmetros!$K2,Parâmetros!$J2,0) -> 12000 | K19: =IF(K$2>=Parâmetros!$K2,Parâmetros!$J2,0) -> 12000 | ... O19: =IF(O$2>=Parâmetros!$K2,Parâmetros!$J2,0) -> 12000 | P19: =SUM(D19:O19) -> 84000
A20: =Parâmetros!A3 -> P02 | B20: =Parâmetros!B3 -> Recompra + campanhas personalizadas | C20: =Parâmetros!C3 -> Marketplace e e-commerce | D20: =IF(D$2>=Parâmetros!$K3,Parâmetros!$J3,0) -> 0 | E20: =IF(E$2>=Parâmetros!$K3,Parâmetros!$J3,0) -> 0 | F20: =IF(F$2>=Parâmetros!$K3,Parâmetros!$J3,0) -> 12000 | G20: =IF(G$2>=Parâmetros!$K3,Parâmetros!$J3,0) -> 12000 | H20: =IF(H$2>=Parâmetros!$K3,Parâmetros!$J3,0) -> 12000 | I20: =IF(I$2>=Parâmetros!$K3,Parâmetros!$J3,0) -> 12000 | J20: =IF(J$2>=Parâmetros!$K3,Parâmetros!$J3,0) -> 12000 | K20: =IF(K$2>=Parâmetros!$K3,Parâmetros!$J3,0) -> 12000 | ... O20: =IF(O$2>=Parâmetros!$K3,Parâmetros!$J3,0) -> 12000 | P20: =SUM(D20:O20) -> 120000
A21: =Parâmetros!A4 -> P03 | B21: =Parâmetros!B4 -> Agente de tratativa de atrasos | C21: =Parâmetros!C4 -> Logística | D21: =IF(D$2>=Parâmetros!$K4,Parâmetros!$J4,0) -> 0 | E21: =IF(E$2>=Parâmetros!$K4,Parâmetros!$J4,0) -> 0 | F21: =IF(F$2>=Parâmetros!$K4,Parâmetros!$J4,0) -> 0 | G21: =IF(G$2>=Parâmetros!$K4,Parâmetros!$J4,0) -> 0 | H21: =IF(H$2>=Parâmetros!$K4,Parâmetros!$J4,0) -> 0 | I21: =IF(I$2>=Parâmetros!$K4,Parâmetros!$J4,0) -> 0 | J21: =IF(J$2>=Parâmetros!$K4,Parâmetros!$J4,0) -> 9000 | K21: =IF(K$2>=Parâmetros!$K4,Parâmetros!$J4,0) -> 9000 | ... O21: =IF(O$2>=Parâmetros!$K4,Parâmetros!$J4,0) -> 9000 | P21: =SUM(D21:O21) -> 54000
A22: =Parâmetros!A5 -> P04 | B22: =Parâmetros!B5 -> App de escala de equipe | C22: =Parâmetros!C5 -> Lojas físicas | D22: =IF(D$2>=Parâmetros!$K5,Parâmetros!$J5,0) -> 0 | E22: =IF(E$2>=Parâmetros!$K5,Parâmetros!$J5,0) -> 0 | F22: =IF(F$2>=Parâmetros!$K5,Parâmetros!$J5,0) -> 0 | G22: =IF(G$2>=Parâmetros!$K5,Parâmetros!$J5,0) -> 0 | H22: =IF(H$2>=Parâmetros!$K5,Parâmetros!$J5,0) -> 0 | I22: =IF(I$2>=Parâmetros!$K5,Parâmetros!$J5,0) -> 0 | J22: =IF(J$2>=Parâmetros!$K5,Parâmetros!$J5,0) -> 0 | K22: =IF(K$2>=Parâmetros!$K5,Parâmetros!$J5,0) -> 600 | ... O22: =IF(O$2>=Parâmetros!$K5,Parâmetros!$J5,0) -> 600 | P22: =SUM(D22:O22) -> 3000
A23: =Parâmetros!A6 -> P05 | B23: =Parâmetros!B6 -> Assistentes de IA de uso geral | C23: =Parâmetros!C6 -> Lojas físicas e áreas corporativas | D23: =IF(D$2>=Parâmetros!$K6,Parâmetros!$J6,0) -> 0 | E23: =IF(E$2>=Parâmetros!$K6,Parâmetros!$J6,0) -> 0 | F23: =IF(F$2>=Parâmetros!$K6,Parâmetros!$J6,0) -> 0 | G23: =IF(G$2>=Parâmetros!$K6,Parâmetros!$J6,0) -> 0 | H23: =IF(H$2>=Parâmetros!$K6,Parâmetros!$J6,0) -> 0 | I23: =IF(I$2>=Parâmetros!$K6,Parâmetros!$J6,0) -> 0 | J23: =IF(J$2>=Parâmetros!$K6,Parâmetros!$J6,0) -> 0 | K23: =IF(K$2>=Parâmetros!$K6,Parâmetros!$J6,0) -> 0 | ... O23: =IF(O$2>=Parâmetros!$K6,Parâmetros!$J6,0) -> 0 | P23: =SUM(D23:O23) -> 0
A24: =Parâmetros!A7 -> P06 | B24: =Parâmetros!B7 -> Modelo de crédito a sellers | C24: =Parâmetros!C7 -> Serviços financeiros | D24: =IF(D$2>=Parâmetros!$K7,Parâmetros!$J7,0) -> 35000 | E24: =IF(E$2>=Parâmetros!$K7,Parâmetros!$J7,0) -> 35000 | F24: =IF(F$2>=Parâmetros!$K7,Parâmetros!$J7,0) -> 35000 | G24: =IF(G$2>=Parâmetros!$K7,Parâmetros!$J7,0) -> 35000 | H24: =IF(H$2>=Parâmetros!$K7,Parâmetros!$J7,0) -> 35000 | I24: =IF(I$2>=Parâmetros!$K7,Parâmetros!$J7,0) -> 35000 | J24: =IF(J$2>=Parâmetros!$K7,Parâmetros!$J7,0) -> 35000 | K24: =IF(K$2>=Parâmetros!$K7,Parâmetros!$J7,0) -> 35000 | ... O24: =IF(O$2>=Parâmetros!$K7,Parâmetros!$J7,0) -> 35000 | P24: =SUM(D24:O24) -> 420000
A25: =Parâmetros!A8 -> P07 | B25: =Parâmetros!B8 -> Antifraude de pagamentos | C25: =Parâmetros!C8 -> Serviços financeiros | D25: =IF(D$2>=Parâmetros!$K8,Parâmetros!$J8,0) -> 95000 | E25: =IF(E$2>=Parâmetros!$K8,Parâmetros!$J8,0) -> 95000 | F25: =IF(F$2>=Parâmetros!$K8,Parâmetros!$J8,0) -> 95000 | G25: =IF(G$2>=Parâmetros!$K8,Parâmetros!$J8,0) -> 95000 | H25: =IF(H$2>=Parâmetros!$K8,Parâmetros!$J8,0) -> 95000 | I25: =IF(I$2>=Parâmetros!$K8,Parâmetros!$J8,0) -> 95000 | J25: =IF(J$2>=Parâmetros!$K8,Parâmetros!$J8,0) -> 95000 | K25: =IF(K$2>=Parâmetros!$K8,Parâmetros!$J8,0) -> 95000 | ... O25: =IF(O$2>=Parâmetros!$K8,Parâmetros!$J8,0) -> 95000 | P25: =SUM(D25:O25) -> 1140000
A26: =Parâmetros!A9 -> P08 | B26: =Parâmetros!B9 -> Assistente interno de RH e políticas | C26: =Parâmetros!C9 -> Corporativo | D26: =IF(D$2>=Parâmetros!$K9,Parâmetros!$J9,0) -> 0 | E26: =IF(E$2>=Parâmetros!$K9,Parâmetros!$J9,0) -> 0 | F26: =IF(F$2>=Parâmetros!$K9,Parâmetros!$J9,0) -> 0 | G26: =IF(G$2>=Parâmetros!$K9,Parâmetros!$J9,0) -> 0 | H26: =IF(H$2>=Parâmetros!$K9,Parâmetros!$J9,0) -> 0 | I26: =IF(I$2>=Parâmetros!$K9,Parâmetros!$J9,0) -> 0 | J26: =IF(J$2>=Parâmetros!$K9,Parâmetros!$J9,0) -> 0 | K26: =IF(K$2>=Parâmetros!$K9,Parâmetros!$J9,0) -> 0 | ... O26: =IF(O$2>=Parâmetros!$K9,Parâmetros!$J9,0) -> 8000 | P26: =SUM(D26:O26) -> 32000
A27: =Parâmetros!A10 -> X1 | B27: =Parâmetros!B10 -> Recursos de nuvem sem piloto atribuído | C27: =Parâmetros!C10 -> Não atribuído | D27: =IF(D$2>=Parâmetros!$K10,Parâmetros!$J10,0) -> 0 | E27: =IF(E$2>=Parâmetros!$K10,Parâmetros!$J10,0) -> 0 | F27: =IF(F$2>=Parâmetros!$K10,Parâmetros!$J10,0) -> 0 | G27: =IF(G$2>=Parâmetros!$K10,Parâmetros!$J10,0) -> 0 | H27: =IF(H$2>=Parâmetros!$K10,Parâmetros!$J10,0) -> 0 | I27: =IF(I$2>=Parâmetros!$K10,Parâmetros!$J10,0) -> 0 | J27: =IF(J$2>=Parâmetros!$K10,Parâmetros!$J10,0) -> 0 | K27: =IF(K$2>=Parâmetros!$K10,Parâmetros!$J10,0) -> 85000 | ... O27: =IF(O$2>=Parâmetros!$K10,Parâmetros!$J10,0) -> 85000 | P27: =SUM(D27:O27) -> 425000
B28: Total | D28: =SUM(D19:D27) -> 130000 | E28: =SUM(E19:E27) -> 130000 | F28: =SUM(F19:F27) -> 142000 | G28: =SUM(G19:G27) -> 142000 | H28: =SUM(H19:H27) -> 142000 | I28: =SUM(I19:I27) -> 154000 | J28: =SUM(J19:J27) -> 163000 | K28: =SUM(K19:K27) -> 248600 | ... P28: =SUM(P19:P27) -> 2278000
A31: Custo total por piloto
A32: ID | B32: Piloto | C32: Unidade | D32: set/25 | E32: out/25 | F32: nov/25 | G32: dez/25 | H32: jan/26 | I32: fev/26 | J32: mar/26 | K32: abr/26 | L32: mai/26 | M32: jun/26 | N32: jul/26 | O32: ago/26 | P32: Total 12 meses
A33: =A5 -> P01 | B33: =B5 -> Agente de SAC com RAG | C33: =C5 -> Marketplace e e-commerce | D33: =D5+D19 -> 0 | E33: =E5+E19 -> 0 | F33: =F5+F19 -> 0 | G33: =G5+G19 -> 0 | H33: =H5+H19 -> 0 | I33: =I5+I19 -> 95258.067 | J33: =J5+J19 -> 109533.81 | K33: =K5+K19 -> 99961.117 | ... O33: =O5+O19 -> 107124.62 | P33: =SUM(D33:O33) -> 693666.39
A34: =A6 -> P02 | B34: =B6 -> Recompra + campanhas personalizadas | C34: =C6 -> Marketplace e e-commerce | D34: =D6+D20 -> 0 | E34: =E6+E20 -> 0 | F34: =F6+F20 -> 17793.75 | G34: =G6+G20 -> 17793.75 | H34: =H6+H20 -> 17793.75 | I34: =I6+I20 -> 17793.75 | J34: =J6+J20 -> 17793.75 | K34: =K6+K20 -> 17793.75 | ... O34: =O6+O20 -> 17793.75 | P34: =SUM(D34:O34) -> 177937.5
A35: =A7 -> P03 | B35: =B7 -> Agente de tratativa de atrasos | C35: =C7 -> Logística | D35: =D7+D21 -> 0 | E35: =E7+E21 -> 0 | F35: =F7+F21 -> 0 | G35: =G7+G21 -> 0 | H35: =H7+H21 -> 0 | I35: =I7+I21 -> 0 | J35: =J7+J21 -> 261144 | K35: =K7+K21 -> 72184.32 | ... O35: =O7+O21 -> 119350.08 | P35: =SUM(D35:O35) -> 607678.56
A36: =A8 -> P04 | B36: =B8 -> App de escala de equipe | C36: =C8 -> Lojas físicas | D36: =D8+D22 -> 0 | E36: =E8+E22 -> 0 | F36: =F8+F22 -> 0 | G36: =G8+G22 -> 0 | H36: =H8+H22 -> 0 | I36: =I8+I22 -> 0 | J36: =J8+J22 -> 0 | K36: =K8+K22 -> 600 | ... O36: =O8+O22 -> 600 | P36: =SUM(D36:O36) -> 3000
A37: =A9 -> P05 | B37: =B9 -> Assistentes de IA de uso geral | C37: =C9 -> Lojas físicas e áreas corporativas | D37: =D9+D23 -> 13200 | E37: =E9+E23 -> 16170 | F37: =F9+F23 -> 19250 | G37: =G9+G23 -> 22220 | H37: =H9+H23 -> 25190 | I37: =I9+I23 -> 28160 | J37: =J9+J23 -> 31240 | K37: =K9+K23 -> 34210 | ... O37: =O9+O23 -> 46200 | P37: =SUM(D37:O37) -> 356400
A38: =A10 -> P06 | B38: =B10 -> Modelo de crédito a sellers | C38: =C10 -> Serviços financeiros | D38: =D10+D24 -> 35000 | E38: =E10+E24 -> 35000 | F38: =F10+F24 -> 35000 | G38: =G10+G24 -> 35000 | H38: =H10+H24 -> 35000 | I38: =I10+I24 -> 35000 | J38: =J10+J24 -> 35000 | K38: =K10+K24 -> 35000 | ... O38: =O10+O24 -> 35000 | P38: =SUM(D38:O38) -> 420000
A39: =A11 -> P07 | B39: =B11 -> Antifraude de pagamentos | C39: =C11 -> Serviços financeiros | D39: =D11+D25 -> 95000 | E39: =E11+E25 -> 95000 | F39: =F11+F25 -> 95000 | G39: =G11+G25 -> 95000 | H39: =H11+H25 -> 95000 | I39: =I11+I25 -> 95000 | J39: =J11+J25 -> 95000 | K39: =K11+K25 -> 95000 | ... O39: =O11+O25 -> 95000 | P39: =SUM(D39:O39) -> 1140000
A40: =A12 -> P08 | B40: =B12 -> Assistente interno de RH e políticas | C40: =C12 -> Corporativo | D40: =D12+D26 -> 0 | E40: =E12+E26 -> 0 | F40: =F12+F26 -> 0 | G40: =G12+G26 -> 0 | H40: =H12+H26 -> 0 | I40: =I12+I26 -> 0 | J40: =J12+J26 -> 0 | K40: =K12+K26 -> 0 | ... O40: =O12+O26 -> 13356 | P40: =SUM(D40:O40) -> 53424
A41: =A13 -> X1 | B41: =B13 -> Recursos de nuvem sem piloto atribuído | C41: =C13 -> Não atribuído | D41: =D13+D27 -> 0 | E41: =E13+E27 -> 0 | F41: =F13+F27 -> 0 | G41: =G13+G27 -> 0 | H41: =H13+H27 -> 0 | I41: =I13+I27 -> 0 | J41: =J13+J27 -> 0 | K41: =K13+K27 -> 85000 | ... O41: =O13+O27 -> 85000 | P41: =SUM(D41:O41) -> 425000
B42: Total geral | D42: =SUM(D33:D41) -> 143200 | E42: =SUM(E33:E41) -> 146170 | F42: =SUM(F33:F41) -> 167043.75 | G42: =SUM(G33:G41) -> 170013.75 | H42: =SUM(H33:H41) -> 172983.75 | I42: =SUM(I33:I41) -> 271211.82 | J42: =SUM(J33:J41) -> 549711.56 | K42: =SUM(K33:K41) -> 439749.19 | ... P42: =SUM(P33:P41) -> 3877106.5
A45: Custo total por unidade
B46: Unidade | D46: set/25 | E46: out/25 | F46: nov/25 | G46: dez/25 | H46: jan/26 | I46: fev/26 | J46: mar/26 | K46: abr/26 | L46: mai/26 | M46: jun/26 | N46: jul/26 | O46: ago/26 | P46: Total 12 meses
...

Sheet Gráfico
